# Python asyncio Timeout Mechanism - Comprehensive Guide

## Overview

Python's asyncio provides robust mechanisms for managing timeouts in asynchronous code. Timeouts are essential for preventing coroutines from blocking the event loop indefinitely and ensuring resources are properly released if an operation takes too long.

### Key Concepts:
- A timeout sets a maximum allowable duration for an async operation
- If the operation doesn't complete in time, asyncio raises an exception (commonly `asyncio.TimeoutError`)
- Proper timeout use ensures your async application remains responsive and prevents resource leaks

## Main Timeout Mechanisms

### 1. asyncio.timeout() (Python 3.11+)

An asynchronous context manager recommended for new code to control timeouts in a more readable and maintainable way.

```python
import asyncio

async def slow_task():
    await asyncio.sleep(10)
    return "Finished"

async def main():
    try:
        async with asyncio.timeout(5):
            result = await slow_task()
            print(result)
    except asyncio.TimeoutError:
        print("The task timed out.")

asyncio.run(main())
```

**How it works:**
- Enter the context with `async with asyncio.timeout(seconds):`
- Any coroutine awaited inside this block must finish before the timeout
- If not, a TimeoutError is raised (which you can catch)
- Recommended for new code due to its clarity and proper resource handling

### 2. asyncio.wait_for()

A function that wraps a coroutine, waits for its completion up to a specified timeout, and cancels it if the timeout expires.

```python
import asyncio

async def slow_operation():
    await asyncio.sleep(10)
    return "Done"

async def main():
    try:
        result = await asyncio.wait_for(slow_operation(), timeout=5)
        print(result)
    except asyncio.TimeoutError:
        print("The operation timed out - it took longer than 5 seconds")

asyncio.run(main())
```

**How it works:**
- Pass the coroutine as the first argument and the maximum time as `timeout`
- If the coroutine doesn't finish in time, it is immediately cancelled, and a TimeoutError is raised
- Ensures that system resources are released promptly since the coroutine is properly cancelled

## Comparison Table

| Mechanism          | Syntax/How to Use            | Exception Raised      | Version Suitability     | Notes                                                    |
|--------------------|------------------------------|----------------------|------------------------|----------------------------------------------------------|
| asyncio.timeout()  | async with asyncio.timeout() | asyncio.TimeoutError | Python 3.11+           | Preferred for new code; context manager, readable        |
| asyncio.wait_for() | await asyncio.wait_for()     | asyncio.TimeoutError | All supported versions | Wraps coroutine; cancels on timeout; good for single await |

## Internal Implementation Details

### How asyncio Implements Timeouts Internally

- Under the hood, timeouts work by wrapping your coroutine in a `Task` and using the event loop's timing and cancellation features to enforce deadlines
- For `asyncio.wait_for()`, the coroutine is scheduled as a `Task`. asyncio then uses the event loop to schedule a callback after the timeout period
- If the coroutine finishes before the timeout, its result is returned. If not, the task is cancelled

### What Happens When a Timeout Occurs

1. **Timeout Triggers**: The timeout handler triggers `task.cancel()`, sending a cancellation request to the coroutine
2. **CancelledError**: This causes the coroutine to immediately receive a `CancelledError` exception at its next suspension point (i.e., any `await`)
3. **Exception Translation**: If using `asyncio.timeout()` (Python 3.11+), this context manager catches the `CancelledError` and raises a `TimeoutError` instead
4. **Propagation**: The underlying coroutine can handle `CancelledError` with a `try/except` block. If not handled, the cancellation propagates, and the coroutine stops

### Cancellation Flow Summary:
1. Coroutine is wrapped in a Task
2. Timeout triggers `task.cancel()`
3. Coroutine receives `CancelledError` on next `await`
4. If not caught, coroutine ends
5. With `asyncio.timeout()`, this is translated to a `TimeoutError` for clarity

## Best Practices

1. **Always use timeouts for potentially blocking or slow operations**: This prevents your event loop from being blocked indefinitely by slow network calls, disk IO, or other external dependencies

2. **Prefer asyncio.timeout() for new code**: It offers greater clarity and is easier to use for composing multiple await statements within a timeout block

3. **Handle asyncio.TimeoutError exceptions**: Always catch this exception to implement graceful error handling and resource cleanup

4. **Avoid excessively short timeouts**: Choose durations that balance responsiveness with your application's tolerance for latency and false positives

5. **Use cancellation wisely**: When a timeout triggers, ensure any necessary cleanup in your coroutine to avoid leaving resources (like open files or network connections) in an inconsistent state

## Edge Cases and Gotchas

### 1. Coroutine May Ignore Cancellation
If your coroutine catches `CancelledError` and suppresses it, timeout cancellation will not propagate. This could result in "zombie" coroutines that keep running after the timeout.

```python
# BAD: Suppressing CancelledError
async def bad_coroutine():
    try:
        await asyncio.sleep(10)
    except asyncio.CancelledError:
        pass  # Don't do this!
        
# GOOD: Cleanup and re-raise
async def good_coroutine():
    try:
        await asyncio.sleep(10)
    except asyncio.CancelledError:
        print("Cancelled! Cleaning up.")
        # Do cleanup here
        raise  # Always re-raise!
```

### 2. Cleanup Required
It's best practice to always allow `CancelledError` to propagate (or do necessary cleanup before re-raising it). Otherwise, resources such as file handles or network connections might leak.

### 3. Timeouts Don't Kill Work Immediately
Cancellation occurs at the next `await` or yield point. If a coroutine is "stuck" in CPU-bound work without yielding, it won't be interrupted until it next awaits.

```python
# This won't be interrupted by timeout until the loop finishes
async def cpu_bound():
    for i in range(1000000000):
        pass  # CPU-bound work
    await asyncio.sleep(0)  # Only here can cancellation occur
```

### 4. Nested Timeouts and Chaining
Be careful if you nest timeouts; catching and suppressing one may inadvertently hide others.

### 5. Difference Between wait_for and timeout
With `asyncio.wait_for()`, you get a `TimeoutError` when the timeout fires, but if you cancel the outer task, it may not always propagate cleanly. The `asyncio.timeout()` context manager provides a more predictable approach by controlling how exceptions are translated.

## Practical Examples

### Example 1: Basic Timeout with Cleanup

```python
import asyncio

async def database_operation():
    connection = None
    try:
        connection = await connect_to_database()
        await asyncio.sleep(10)  # Simulate slow query
        return await connection.fetch_data()
    except asyncio.CancelledError:
        print("Database operation cancelled, cleaning up...")
        if connection:
            await connection.close()
        raise

async def main():
    try:
        async with asyncio.timeout(5):
            result = await database_operation()
            print(f"Result: {result}")
    except asyncio.TimeoutError:
        print("Database operation timed out after 5 seconds")

asyncio.run(main())
```

### Example 2: Multiple Operations with Timeout

```python
import asyncio

async def fetch_data_from_api(api_url):
    # Simulate API call
    await asyncio.sleep(2)
    return f"Data from {api_url}"

async def main():
    apis = ["api1", "api2", "api3"]
    
    try:
        async with asyncio.timeout(5):
            tasks = [fetch_data_from_api(api) for api in apis]
            results = await asyncio.gather(*tasks)
            print(f"All results: {results}")
    except asyncio.TimeoutError:
        print("Failed to fetch all data within 5 seconds")

asyncio.run(main())
```

### Example 3: Handling Partial Results

```python
import asyncio

async def fetch_with_individual_timeout(url, timeout=2):
    try:
        await asyncio.wait_for(fetch_data(url), timeout=timeout)
        return {"url": url, "status": "success"}
    except asyncio.TimeoutError:
        return {"url": url, "status": "timeout"}

async def main():
    urls = ["fast-api", "slow-api", "normal-api"]
    
    # Give each operation its own timeout
    tasks = [fetch_with_individual_timeout(url) for url in urls]
    results = await asyncio.gather(*tasks)
    
    successful = [r for r in results if r["status"] == "success"]
    failed = [r for r in results if r["status"] == "timeout"]
    
    print(f"Successful: {len(successful)}")
    print(f"Failed: {len(failed)}")

asyncio.run(main())
```

## Summary

Timeouts are a fundamental part of robust asynchronous programs. Use `asyncio.timeout()` for modern code and `asyncio.wait_for()` for single operations or compatibility with older Python versions. Always ensure proper exception handling to maintain system stability and resource correctness.

Key takeaways:
- asyncio timeouts use Task cancellation, not just exception raising
- When the timeout occurs, the coroutine is cancelled by raising `CancelledError` at its next suspend point
- Always handle cleanup on cancellation, and never suppress `CancelledError` unless you re-raise it
- Edge cases involve coroutines with suppressed or missed cancellations and CPU-bound coroutines that can't be cancelled until they yield